
Exception caught at 2021-11-03 13:53:41.301624:
Traceback (most recent call last):
  File "internal/testpy/test_framework.py", line 238, in <module>
    main()
  File "internal/testpy/test_framework.py", line 57, in main
    input("Press Enter To Exit...")
EOFError

Exception caught at 2021-11-03 13:53:42.764110:
Traceback (most recent call last):
  File "internal/testpy/test_framework.py", line 238, in <module>
    main()
  File "internal/testpy/test_framework.py", line 57, in main
    input("Press Enter To Exit...")
EOFError: EOF when reading a line

Exception caught at 2021-11-03 21:45:31.698153:
Traceback (most recent call last):
  File "internal/testpy/test_framework.py", line 238, in <module>
    main()
  File "internal/testpy/test_framework.py", line 57, in main
    input("Press Enter To Exit...")
EOFError

Exception caught at 2021-11-03 21:46:59.022773:
Traceback (most recent call last):
  File "internal/testpy/test_framework.py", line 238, in <module>
    main()
  File "internal/testpy/test_framework.py", line 57, in main
    input("Press Enter To Exit...")
EOFError

Exception caught at 2021-11-04 16:08:49.691731:
Traceback (most recent call last):
  File "internal/testpy/test_framework.py", line 238, in <module>
    main()
  File "internal/testpy/test_framework.py", line 57, in main
    input("Press Enter To Exit...")
EOFError

Exception caught at 2021-11-04 16:08:49.691336:
Traceback (most recent call last):
  File "internal/testpy/test_framework.py", line 238, in <module>
    main()
  File "internal/testpy/test_framework.py", line 57, in main
    input("Press Enter To Exit...")
EOFError

Exception caught at 2021-11-05 19:05:47.131383:
Traceback (most recent call last):
  File "internal/testpy/test_framework.py", line 238, in <module>
    main()
  File "internal/testpy/test_framework.py", line 57, in main
    input("Press Enter To Exit...")
EOFError

Exception caught at 2021-11-05 19:07:38.957081:
Traceback (most recent call last):
  File "internal/testpy/test_framework.py", line 238, in <module>
    main()
  File "internal/testpy/test_framework.py", line 57, in main
    input("Press Enter To Exit...")
EOFError

Exception caught at 2021-11-05 19:19:08.922284:
Traceback (most recent call last):
  File "internal/testpy/test_framework.py", line 238, in <module>
    main()
  File "internal/testpy/test_framework.py", line 57, in main
    input("Press Enter To Exit...")
EOFError

Exception caught at 2021-11-05 19:19:08.926151:
Traceback (most recent call last):
  File "internal/testpy/test_framework.py", line 238, in <module>
    main()
  File "internal/testpy/test_framework.py", line 57, in main
    input("Press Enter To Exit...")
EOFError

Exception caught at 2021-11-05 19:19:08.928893:
Traceback (most recent call last):
  File "internal/testpy/test_framework.py", line 238, in <module>
    main()
  File "internal/testpy/test_framework.py", line 57, in main
    input("Press Enter To Exit...")
EOFError

Exception caught at 2021-11-05 19:19:08.929193:
Traceback (most recent call last):
  File "internal/testpy/test_framework.py", line 238, in <module>
    main()
  File "internal/testpy/test_framework.py", line 57, in main
    input("Press Enter To Exit...")
EOFError

Exception caught at 2021-11-05 19:19:08.932501:
Traceback (most recent call last):
  File "internal/testpy/test_framework.py", line 238, in <module>
    main()
  File "internal/testpy/test_framework.py", line 57, in main
    input("Press Enter To Exit...")
EOFError

Exception caught at 2021-11-05 19:19:08.934052:
Traceback (most recent call last):
  File "internal/testpy/test_framework.py", line 238, in <module>
    main()
  File "internal/testpy/test_framework.py", line 57, in main
    input("Press Enter To Exit...")
EOFError

Exception caught at 2021-11-05 21:06:00.675204:
Traceback (most recent call last):
  File "internal/testpy/test_framework.py", line 238, in <module>
    main()
  File "internal/testpy/test_framework.py", line 57, in main
    input("Press Enter To Exit...")
EOFError

Exception caught at 2021-11-05 21:15:24.632562:
Traceback (most recent call last):
  File "internal/testpy/test_framework.py", line 238, in <module>
    main()
  File "internal/testpy/test_framework.py", line 57, in main
    input("Press Enter To Exit...")
EOFError

Exception caught at 2021-11-05 21:15:24.632831:
Traceback (most recent call last):
  File "internal/testpy/test_framework.py", line 238, in <module>
    main()
  File "internal/testpy/test_framework.py", line 57, in main
    input("Press Enter To Exit...")
EOFError

Exception caught at 2021-11-05 21:18:54.395643:
Traceback (most recent call last):
  File "internal/testpy/test_framework.py", line 238, in <module>
    main()
  File "internal/testpy/test_framework.py", line 57, in main
    input("Press Enter To Exit...")
EOFError

Exception caught at 2021-11-05 21:18:54.396617:
Traceback (most recent call last):
  File "internal/testpy/test_framework.py", line 238, in <module>
    main()
  File "internal/testpy/test_framework.py", line 57, in main
    input("Press Enter To Exit...")
EOFError

Exception caught at 2021-11-05 21:18:54.396373:
Traceback (most recent call last):
  File "internal/testpy/test_framework.py", line 238, in <module>
    main()
  File "internal/testpy/test_framework.py", line 57, in main
    input("Press Enter To Exit...")
EOFError

Exception caught at 2021-11-05 21:18:54.397371:
Traceback (most recent call last):
  File "internal/testpy/test_framework.py", line 238, in <module>
    main()
  File "internal/testpy/test_framework.py", line 57, in main
    input("Press Enter To Exit...")
EOFError

Exception caught at 2021-11-05 21:18:54.395978:
Traceback (most recent call last):
  File "internal/testpy/test_framework.py", line 238, in <module>
    main()
  File "internal/testpy/test_framework.py", line 57, in main
    input("Press Enter To Exit...")
EOFError

Exception caught at 2021-11-05 21:18:54.396986:
Traceback (most recent call last):
  File "internal/testpy/test_framework.py", line 238, in <module>
    main()
  File "internal/testpy/test_framework.py", line 57, in main
    input("Press Enter To Exit...")
EOFError

Exception caught at 2021-11-05 21:18:54.400553:
Traceback (most recent call last):
  File "internal/testpy/test_framework.py", line 238, in <module>
    main()
  File "internal/testpy/test_framework.py", line 57, in main
    input("Press Enter To Exit...")
EOFError

Exception caught at 2021-11-05 21:18:54.404258:
Traceback (most recent call last):
  File "internal/testpy/test_framework.py", line 238, in <module>
    main()
  File "internal/testpy/test_framework.py", line 57, in main
    input("Press Enter To Exit...")
EOFError

Exception caught at 2021-11-05 21:18:54.411277:
Traceback (most recent call last):
  File "internal/testpy/test_framework.py", line 238, in <module>
    main()
  File "internal/testpy/test_framework.py", line 57, in main
    input("Press Enter To Exit...")
EOFError

Exception caught at 2021-11-05 21:18:54.411280:
Traceback (most recent call last):
  File "internal/testpy/test_framework.py", line 238, in <module>
    main()
  File "internal/testpy/test_framework.py", line 57, in main
    input("Press Enter To Exit...")
EOFError

Exception caught at 2021-11-05 21:18:54.397809:
Traceback (most recent call last):
  File "internal/testpy/test_framework.py", line 238, in <module>
    main()
  File "internal/testpy/test_framework.py", line 57, in main
    input("Press Enter To Exit...")
EOFError

Exception caught at 2021-11-05 21:18:54.399537:
Traceback (most recent call last):
  File "internal/testpy/test_framework.py", line 238, in <module>
    main()
  File "internal/testpy/test_framework.py", line 57, in main
    input("Press Enter To Exit...")
EOFError

Exception caught at 2021-11-05 21:18:54.413631:
Traceback (most recent call last):
  File "internal/testpy/test_framework.py", line 238, in <module>
    main()
  File "internal/testpy/test_framework.py", line 57, in main
    input("Press Enter To Exit...")
EOFError

Exception caught at 2021-11-05 21:18:54.421620:
Traceback (most recent call last):
  File "internal/testpy/test_framework.py", line 238, in <module>
    main()
  File "internal/testpy/test_framework.py", line 57, in main
    input("Press Enter To Exit...")
EOFError

Exception caught at 2021-11-05 21:18:54.421611:
Traceback (most recent call last):
  File "internal/testpy/test_framework.py", line 238, in <module>
    main()
  File "internal/testpy/test_framework.py", line 57, in main
    input("Press Enter To Exit...")
EOFError

Exception caught at 2021-11-05 21:18:54.404661:
Traceback (most recent call last):
  File "/usr/lib64/python3.6/tkinter/__init__.py", line 1705, in __call__
    return self.func(*args)
  File "/home/evang/CPRE381_Fall/GIT/CprE381/Project 1/cpre-381-toolflow-fall-2021-master/internal/testpy/run_gui.py", line 197, in chooseSelectedFiles
    test_framework.queueSimulation(asm_files_to_run, options)
  File "/home/evang/CPRE381_Fall/GIT/CprE381/Project 1/cpre-381-toolflow-fall-2021-master/internal/testpy/test_framework.py", line 65, in queueSimulation
    runSimulation(x,simOptions)
  File "/home/evang/CPRE381_Fall/GIT/CprE381/Project 1/cpre-381-toolflow-fall-2021-master/internal/testpy/test_framework.py", line 72, in runSimulation
    options['asm-path'] = mars.run_sim(asm_file=asm_Path)
  File "/home/evang/CPRE381_Fall/GIT/CprE381/Project 1/cpre-381-toolflow-fall-2021-master/internal/testpy/mars.py", line 72, in run_sim
    return run_sim()
  File "/home/evang/CPRE381_Fall/GIT/CprE381/Project 1/cpre-381-toolflow-fall-2021-master/internal/testpy/mars.py", line 45, in run_sim
    path = input('>').strip()
EOFError

During handling of the above exception, another exception occurred:

Traceback (most recent call last):
  File "internal/testpy/test_framework.py", line 238, in <module>
    main()
  File "internal/testpy/test_framework.py", line 55, in main
    run_gui.guiMain()
  File "/home/evang/CPRE381_Fall/GIT/CprE381/Project 1/cpre-381-toolflow-fall-2021-master/internal/testpy/run_gui.py", line 156, in guiMain
    window.mainloop()
  File "/usr/lib64/python3.6/tkinter/__init__.py", line 1283, in mainloop
    self.tk.mainloop(n)
  File "/usr/lib64/python3.6/tkinter/__init__.py", line 1709, in __call__
    self.widget._report_exception()
  File "/usr/lib64/python3.6/tkinter/__init__.py", line 1452, in _report_exception
    root.report_callback_exception(exc, val, tb)
  File "/usr/lib64/python3.6/tkinter/__init__.py", line 2094, in report_callback_exception
    print("Exception in Tkinter callback", file=sys.stderr)
OSError: [Errno 5] Input/output error

Exception caught at 2021-11-05 21:18:54.421557:
Traceback (most recent call last):
  File "/usr/lib64/python3.6/tkinter/__init__.py", line 1705, in __call__
    return self.func(*args)
  File "/home/evang/CPRE381_Fall/GIT/CprE381/Project 1/cpre-381-toolflow-fall-2021-master/internal/testpy/run_gui.py", line 197, in chooseSelectedFiles
    test_framework.queueSimulation(asm_files_to_run, options)
  File "/home/evang/CPRE381_Fall/GIT/CprE381/Project 1/cpre-381-toolflow-fall-2021-master/internal/testpy/test_framework.py", line 65, in queueSimulation
    runSimulation(x,simOptions)
  File "/home/evang/CPRE381_Fall/GIT/CprE381/Project 1/cpre-381-toolflow-fall-2021-master/internal/testpy/test_framework.py", line 72, in runSimulation
    options['asm-path'] = mars.run_sim(asm_file=asm_Path)
  File "/home/evang/CPRE381_Fall/GIT/CprE381/Project 1/cpre-381-toolflow-fall-2021-master/internal/testpy/mars.py", line 72, in run_sim
    return run_sim()
  File "/home/evang/CPRE381_Fall/GIT/CprE381/Project 1/cpre-381-toolflow-fall-2021-master/internal/testpy/mars.py", line 45, in run_sim
    path = input('>').strip()
EOFError

During handling of the above exception, another exception occurred:

Traceback (most recent call last):
  File "internal/testpy/test_framework.py", line 238, in <module>
    main()
  File "internal/testpy/test_framework.py", line 55, in main
    run_gui.guiMain()
  File "/home/evang/CPRE381_Fall/GIT/CprE381/Project 1/cpre-381-toolflow-fall-2021-master/internal/testpy/run_gui.py", line 156, in guiMain
    window.mainloop()
  File "/usr/lib64/python3.6/tkinter/__init__.py", line 1283, in mainloop
    self.tk.mainloop(n)
  File "/usr/lib64/python3.6/tkinter/__init__.py", line 1709, in __call__
    self.widget._report_exception()
  File "/usr/lib64/python3.6/tkinter/__init__.py", line 1452, in _report_exception
    root.report_callback_exception(exc, val, tb)
  File "/usr/lib64/python3.6/tkinter/__init__.py", line 2094, in report_callback_exception
    print("Exception in Tkinter callback", file=sys.stderr)
OSError: [Errno 5] Input/output error

Exception caught at 2021-11-05 21:18:57.082048:
Traceback (most recent call last):
  File "internal/testpy/test_framework.py", line 238, in <module>
    main()
  File "internal/testpy/test_framework.py", line 57, in main
    input("Press Enter To Exit...")
EOFError: EOF when reading a line

Exception caught at 2021-11-06 15:51:55.483715:
Traceback (most recent call last):
  File "internal/testpy/test_framework.py", line 238, in <module>
    main()
  File "internal/testpy/test_framework.py", line 57, in main
    input("Press Enter To Exit...")
EOFError

Exception caught at 2021-11-06 15:51:55.485546:
Traceback (most recent call last):
  File "/usr/lib64/python3.6/tkinter/__init__.py", line 1705, in __call__
    return self.func(*args)
  File "/home/evang/CPRE381_Fall/GIT/CprE381/Project 1/cpre-381-toolflow-fall-2021-master/internal/testpy/run_gui.py", line 197, in chooseSelectedFiles
    test_framework.queueSimulation(asm_files_to_run, options)
  File "/home/evang/CPRE381_Fall/GIT/CprE381/Project 1/cpre-381-toolflow-fall-2021-master/internal/testpy/test_framework.py", line 65, in queueSimulation
    runSimulation(x,simOptions)
  File "/home/evang/CPRE381_Fall/GIT/CprE381/Project 1/cpre-381-toolflow-fall-2021-master/internal/testpy/test_framework.py", line 72, in runSimulation
    options['asm-path'] = mars.run_sim(asm_file=asm_Path)
  File "/home/evang/CPRE381_Fall/GIT/CprE381/Project 1/cpre-381-toolflow-fall-2021-master/internal/testpy/mars.py", line 72, in run_sim
    return run_sim()
  File "/home/evang/CPRE381_Fall/GIT/CprE381/Project 1/cpre-381-toolflow-fall-2021-master/internal/testpy/mars.py", line 45, in run_sim
    path = input('>').strip()
EOFError

During handling of the above exception, another exception occurred:

Traceback (most recent call last):
  File "internal/testpy/test_framework.py", line 238, in <module>
    main()
  File "internal/testpy/test_framework.py", line 55, in main
    run_gui.guiMain()
  File "/home/evang/CPRE381_Fall/GIT/CprE381/Project 1/cpre-381-toolflow-fall-2021-master/internal/testpy/run_gui.py", line 156, in guiMain
    window.mainloop()
  File "/usr/lib64/python3.6/tkinter/__init__.py", line 1283, in mainloop
    self.tk.mainloop(n)
  File "/usr/lib64/python3.6/tkinter/__init__.py", line 1709, in __call__
    self.widget._report_exception()
  File "/usr/lib64/python3.6/tkinter/__init__.py", line 1452, in _report_exception
    root.report_callback_exception(exc, val, tb)
  File "/usr/lib64/python3.6/tkinter/__init__.py", line 2094, in report_callback_exception
    print("Exception in Tkinter callback", file=sys.stderr)
OSError: [Errno 5] Input/output error

Exception caught at 2021-11-06 15:51:55.488496:
Traceback (most recent call last):
  File "/usr/lib64/python3.6/tkinter/__init__.py", line 1705, in __call__
    return self.func(*args)
  File "/home/evang/CPRE381_Fall/GIT/CprE381/Project 1/cpre-381-toolflow-fall-2021-master/internal/testpy/run_gui.py", line 197, in chooseSelectedFiles
    test_framework.queueSimulation(asm_files_to_run, options)
  File "/home/evang/CPRE381_Fall/GIT/CprE381/Project 1/cpre-381-toolflow-fall-2021-master/internal/testpy/test_framework.py", line 65, in queueSimulation
    runSimulation(x,simOptions)
  File "/home/evang/CPRE381_Fall/GIT/CprE381/Project 1/cpre-381-toolflow-fall-2021-master/internal/testpy/test_framework.py", line 72, in runSimulation
    options['asm-path'] = mars.run_sim(asm_file=asm_Path)
  File "/home/evang/CPRE381_Fall/GIT/CprE381/Project 1/cpre-381-toolflow-fall-2021-master/internal/testpy/mars.py", line 72, in run_sim
    return run_sim()
  File "/home/evang/CPRE381_Fall/GIT/CprE381/Project 1/cpre-381-toolflow-fall-2021-master/internal/testpy/mars.py", line 45, in run_sim
    path = input('>').strip()
EOFError

During handling of the above exception, another exception occurred:

Traceback (most recent call last):
  File "internal/testpy/test_framework.py", line 238, in <module>
    main()
  File "internal/testpy/test_framework.py", line 55, in main
    run_gui.guiMain()
  File "/home/evang/CPRE381_Fall/GIT/CprE381/Project 1/cpre-381-toolflow-fall-2021-master/internal/testpy/run_gui.py", line 156, in guiMain
    window.mainloop()
  File "/usr/lib64/python3.6/tkinter/__init__.py", line 1283, in mainloop
    self.tk.mainloop(n)
  File "/usr/lib64/python3.6/tkinter/__init__.py", line 1709, in __call__
    self.widget._report_exception()
  File "/usr/lib64/python3.6/tkinter/__init__.py", line 1452, in _report_exception
    root.report_callback_exception(exc, val, tb)
  File "/usr/lib64/python3.6/tkinter/__init__.py", line 2094, in report_callback_exception
    print("Exception in Tkinter callback", file=sys.stderr)
OSError: [Errno 5] Input/output error

Exception caught at 2021-11-06 16:31:30.847106:
Traceback (most recent call last):
  File "internal/testpy/test_framework.py", line 238, in <module>
    main()
  File "internal/testpy/test_framework.py", line 57, in main
    input("Press Enter To Exit...")
EOFError

Exception caught at 2021-11-06 16:31:56.703275:
Traceback (most recent call last):
  File "internal/testpy/test_framework.py", line 238, in <module>
    main()
  File "internal/testpy/test_framework.py", line 57, in main
    input("Press Enter To Exit...")
EOFError

Exception caught at 2021-11-06 16:32:45.332447:
Traceback (most recent call last):
  File "internal/testpy/test_framework.py", line 238, in <module>
    main()
  File "internal/testpy/test_framework.py", line 57, in main
    input("Press Enter To Exit...")
EOFError

Exception caught at 2021-11-06 16:32:45.336642:
Traceback (most recent call last):
  File "/usr/lib64/python3.6/tkinter/__init__.py", line 1705, in __call__
    return self.func(*args)
  File "/home/evang/CPRE381_Fall/GIT/CprE381/Project 1/cpre-381-toolflow-fall-2021-master/internal/testpy/run_gui.py", line 197, in chooseSelectedFiles
    test_framework.queueSimulation(asm_files_to_run, options)
  File "/home/evang/CPRE381_Fall/GIT/CprE381/Project 1/cpre-381-toolflow-fall-2021-master/internal/testpy/test_framework.py", line 65, in queueSimulation
    runSimulation(x,simOptions)
  File "/home/evang/CPRE381_Fall/GIT/CprE381/Project 1/cpre-381-toolflow-fall-2021-master/internal/testpy/test_framework.py", line 72, in runSimulation
    options['asm-path'] = mars.run_sim(asm_file=asm_Path)
  File "/home/evang/CPRE381_Fall/GIT/CprE381/Project 1/cpre-381-toolflow-fall-2021-master/internal/testpy/mars.py", line 72, in run_sim
    return run_sim()
  File "/home/evang/CPRE381_Fall/GIT/CprE381/Project 1/cpre-381-toolflow-fall-2021-master/internal/testpy/mars.py", line 45, in run_sim
    path = input('>').strip()
EOFError

During handling of the above exception, another exception occurred:

Traceback (most recent call last):
  File "internal/testpy/test_framework.py", line 238, in <module>
    main()
  File "internal/testpy/test_framework.py", line 55, in main
    run_gui.guiMain()
  File "/home/evang/CPRE381_Fall/GIT/CprE381/Project 1/cpre-381-toolflow-fall-2021-master/internal/testpy/run_gui.py", line 156, in guiMain
    window.mainloop()
  File "/usr/lib64/python3.6/tkinter/__init__.py", line 1283, in mainloop
    self.tk.mainloop(n)
  File "/usr/lib64/python3.6/tkinter/__init__.py", line 1709, in __call__
    self.widget._report_exception()
  File "/usr/lib64/python3.6/tkinter/__init__.py", line 1452, in _report_exception
    root.report_callback_exception(exc, val, tb)
  File "/usr/lib64/python3.6/tkinter/__init__.py", line 2094, in report_callback_exception
    print("Exception in Tkinter callback", file=sys.stderr)
OSError: [Errno 5] Input/output error

Exception caught at 2021-11-06 16:32:45.338860:
Traceback (most recent call last):
  File "internal/testpy/test_framework.py", line 238, in <module>
    main()
  File "internal/testpy/test_framework.py", line 57, in main
    input("Press Enter To Exit...")
EOFError

Exception caught at 2021-11-06 16:32:45.341230:
Traceback (most recent call last):
  File "internal/testpy/test_framework.py", line 238, in <module>
    main()
  File "internal/testpy/test_framework.py", line 57, in main
    input("Press Enter To Exit...")
EOFError

Exception caught at 2021-11-06 16:32:45.342413:
Traceback (most recent call last):
  File "/usr/lib64/python3.6/tkinter/__init__.py", line 1705, in __call__
    return self.func(*args)
  File "/home/evang/CPRE381_Fall/GIT/CprE381/Project 1/cpre-381-toolflow-fall-2021-master/internal/testpy/run_gui.py", line 197, in chooseSelectedFiles
    test_framework.queueSimulation(asm_files_to_run, options)
  File "/home/evang/CPRE381_Fall/GIT/CprE381/Project 1/cpre-381-toolflow-fall-2021-master/internal/testpy/test_framework.py", line 65, in queueSimulation
    runSimulation(x,simOptions)
  File "/home/evang/CPRE381_Fall/GIT/CprE381/Project 1/cpre-381-toolflow-fall-2021-master/internal/testpy/test_framework.py", line 72, in runSimulation
    options['asm-path'] = mars.run_sim(asm_file=asm_Path)
  File "/home/evang/CPRE381_Fall/GIT/CprE381/Project 1/cpre-381-toolflow-fall-2021-master/internal/testpy/mars.py", line 72, in run_sim
    return run_sim()
  File "/home/evang/CPRE381_Fall/GIT/CprE381/Project 1/cpre-381-toolflow-fall-2021-master/internal/testpy/mars.py", line 45, in run_sim
    path = input('>').strip()
EOFError

During handling of the above exception, another exception occurred:

Traceback (most recent call last):
  File "internal/testpy/test_framework.py", line 238, in <module>
    main()
  File "internal/testpy/test_framework.py", line 55, in main
    run_gui.guiMain()
  File "/home/evang/CPRE381_Fall/GIT/CprE381/Project 1/cpre-381-toolflow-fall-2021-master/internal/testpy/run_gui.py", line 156, in guiMain
    window.mainloop()
  File "/usr/lib64/python3.6/tkinter/__init__.py", line 1283, in mainloop
    self.tk.mainloop(n)
  File "/usr/lib64/python3.6/tkinter/__init__.py", line 1709, in __call__
    self.widget._report_exception()
  File "/usr/lib64/python3.6/tkinter/__init__.py", line 1452, in _report_exception
    root.report_callback_exception(exc, val, tb)
  File "/usr/lib64/python3.6/tkinter/__init__.py", line 2094, in report_callback_exception
    print("Exception in Tkinter callback", file=sys.stderr)
OSError: [Errno 5] Input/output error

Exception caught at 2021-11-06 16:32:45.344944:
Traceback (most recent call last):
  File "internal/testpy/test_framework.py", line 238, in <module>
    main()
  File "internal/testpy/test_framework.py", line 57, in main
    input("Press Enter To Exit...")
EOFError

Exception caught at 2021-11-06 16:32:45.351288:
Traceback (most recent call last):
  File "internal/testpy/test_framework.py", line 238, in <module>
    main()
  File "internal/testpy/test_framework.py", line 57, in main
    input("Press Enter To Exit...")
EOFError

Exception caught at 2021-11-06 16:32:45.351634:
Traceback (most recent call last):
  File "/usr/lib64/python3.6/tkinter/__init__.py", line 1705, in __call__
    return self.func(*args)
  File "/home/evang/CPRE381_Fall/GIT/CprE381/Project 1/cpre-381-toolflow-fall-2021-master/internal/testpy/run_gui.py", line 197, in chooseSelectedFiles
    test_framework.queueSimulation(asm_files_to_run, options)
  File "/home/evang/CPRE381_Fall/GIT/CprE381/Project 1/cpre-381-toolflow-fall-2021-master/internal/testpy/test_framework.py", line 65, in queueSimulation
    runSimulation(x,simOptions)
  File "/home/evang/CPRE381_Fall/GIT/CprE381/Project 1/cpre-381-toolflow-fall-2021-master/internal/testpy/test_framework.py", line 72, in runSimulation
    options['asm-path'] = mars.run_sim(asm_file=asm_Path)
  File "/home/evang/CPRE381_Fall/GIT/CprE381/Project 1/cpre-381-toolflow-fall-2021-master/internal/testpy/mars.py", line 72, in run_sim
    return run_sim()
  File "/home/evang/CPRE381_Fall/GIT/CprE381/Project 1/cpre-381-toolflow-fall-2021-master/internal/testpy/mars.py", line 45, in run_sim
    path = input('>').strip()
EOFError

During handling of the above exception, another exception occurred:

Traceback (most recent call last):
  File "internal/testpy/test_framework.py", line 238, in <module>
    main()
  File "internal/testpy/test_framework.py", line 55, in main
    run_gui.guiMain()
  File "/home/evang/CPRE381_Fall/GIT/CprE381/Project 1/cpre-381-toolflow-fall-2021-master/internal/testpy/run_gui.py", line 156, in guiMain
    window.mainloop()
  File "/usr/lib64/python3.6/tkinter/__init__.py", line 1283, in mainloop
    self.tk.mainloop(n)
  File "/usr/lib64/python3.6/tkinter/__init__.py", line 1709, in __call__
    self.widget._report_exception()
  File "/usr/lib64/python3.6/tkinter/__init__.py", line 1452, in _report_exception
    root.report_callback_exception(exc, val, tb)
  File "/usr/lib64/python3.6/tkinter/__init__.py", line 2094, in report_callback_exception
    print("Exception in Tkinter callback", file=sys.stderr)
OSError: [Errno 5] Input/output error

Exception caught at 2021-11-06 16:32:45.352442:
Traceback (most recent call last):
  File "/usr/lib64/python3.6/tkinter/__init__.py", line 1705, in __call__
    return self.func(*args)
  File "/home/evang/CPRE381_Fall/GIT/CprE381/Project 1/cpre-381-toolflow-fall-2021-master/internal/testpy/run_gui.py", line 197, in chooseSelectedFiles
    test_framework.queueSimulation(asm_files_to_run, options)
  File "/home/evang/CPRE381_Fall/GIT/CprE381/Project 1/cpre-381-toolflow-fall-2021-master/internal/testpy/test_framework.py", line 65, in queueSimulation
    runSimulation(x,simOptions)
  File "/home/evang/CPRE381_Fall/GIT/CprE381/Project 1/cpre-381-toolflow-fall-2021-master/internal/testpy/test_framework.py", line 72, in runSimulation
    options['asm-path'] = mars.run_sim(asm_file=asm_Path)
  File "/home/evang/CPRE381_Fall/GIT/CprE381/Project 1/cpre-381-toolflow-fall-2021-master/internal/testpy/mars.py", line 72, in run_sim
    return run_sim()
  File "/home/evang/CPRE381_Fall/GIT/CprE381/Project 1/cpre-381-toolflow-fall-2021-master/internal/testpy/mars.py", line 45, in run_sim
    path = input('>').strip()
EOFError

During handling of the above exception, another exception occurred:

Traceback (most recent call last):
  File "internal/testpy/test_framework.py", line 238, in <module>
    main()
  File "internal/testpy/test_framework.py", line 55, in main
    run_gui.guiMain()
  File "/home/evang/CPRE381_Fall/GIT/CprE381/Project 1/cpre-381-toolflow-fall-2021-master/internal/testpy/run_gui.py", line 156, in guiMain
    window.mainloop()
  File "/usr/lib64/python3.6/tkinter/__init__.py", line 1283, in mainloop
    self.tk.mainloop(n)
  File "/usr/lib64/python3.6/tkinter/__init__.py", line 1709, in __call__
    self.widget._report_exception()
  File "/usr/lib64/python3.6/tkinter/__init__.py", line 1452, in _report_exception
    root.report_callback_exception(exc, val, tb)
  File "/usr/lib64/python3.6/tkinter/__init__.py", line 2094, in report_callback_exception
    print("Exception in Tkinter callback", file=sys.stderr)
OSError: [Errno 5] Input/output error

Exception caught at 2021-11-06 16:32:45.352800:
Traceback (most recent call last):
  File "/usr/lib64/python3.6/tkinter/__init__.py", line 1705, in __call__
    return self.func(*args)
  File "/home/evang/CPRE381_Fall/GIT/CprE381/Project 1/cpre-381-toolflow-fall-2021-master/internal/testpy/run_gui.py", line 197, in chooseSelectedFiles
    test_framework.queueSimulation(asm_files_to_run, options)
  File "/home/evang/CPRE381_Fall/GIT/CprE381/Project 1/cpre-381-toolflow-fall-2021-master/internal/testpy/test_framework.py", line 65, in queueSimulation
    runSimulation(x,simOptions)
  File "/home/evang/CPRE381_Fall/GIT/CprE381/Project 1/cpre-381-toolflow-fall-2021-master/internal/testpy/test_framework.py", line 72, in runSimulation
    options['asm-path'] = mars.run_sim(asm_file=asm_Path)
  File "/home/evang/CPRE381_Fall/GIT/CprE381/Project 1/cpre-381-toolflow-fall-2021-master/internal/testpy/mars.py", line 72, in run_sim
    return run_sim()
  File "/home/evang/CPRE381_Fall/GIT/CprE381/Project 1/cpre-381-toolflow-fall-2021-master/internal/testpy/mars.py", line 45, in run_sim
    path = input('>').strip()
EOFError

During handling of the above exception, another exception occurred:

Traceback (most recent call last):
  File "internal/testpy/test_framework.py", line 238, in <module>
    main()
  File "internal/testpy/test_framework.py", line 55, in main
    run_gui.guiMain()
  File "/home/evang/CPRE381_Fall/GIT/CprE381/Project 1/cpre-381-toolflow-fall-2021-master/internal/testpy/run_gui.py", line 156, in guiMain
    window.mainloop()
  File "/usr/lib64/python3.6/tkinter/__init__.py", line 1283, in mainloop
    self.tk.mainloop(n)
  File "/usr/lib64/python3.6/tkinter/__init__.py", line 1709, in __call__
    self.widget._report_exception()
  File "/usr/lib64/python3.6/tkinter/__init__.py", line 1452, in _report_exception
    root.report_callback_exception(exc, val, tb)
  File "/usr/lib64/python3.6/tkinter/__init__.py", line 2094, in report_callback_exception
    print("Exception in Tkinter callback", file=sys.stderr)
OSError: [Errno 5] Input/output error

Exception caught at 2021-11-06 17:59:37.951680:
Traceback (most recent call last):
  File "internal/testpy/test_framework.py", line 238, in <module>
    main()
  File "internal/testpy/test_framework.py", line 57, in main
    input("Press Enter To Exit...")
EOFError

Exception caught at 2021-11-06 17:59:37.952093:
Traceback (most recent call last):
  File "internal/testpy/test_framework.py", line 238, in <module>
    main()
  File "internal/testpy/test_framework.py", line 57, in main
    input("Press Enter To Exit...")
EOFError

Exception caught at 2021-11-06 17:59:37.952499:
Traceback (most recent call last):
  File "internal/testpy/test_framework.py", line 238, in <module>
    main()
  File "internal/testpy/test_framework.py", line 57, in main
    input("Press Enter To Exit...")
EOFError

Exception caught at 2021-11-06 17:59:37.952989:
Traceback (most recent call last):
  File "internal/testpy/test_framework.py", line 238, in <module>
    main()
  File "internal/testpy/test_framework.py", line 57, in main
    input("Press Enter To Exit...")
EOFError

Exception caught at 2021-11-06 17:59:37.965965:
Traceback (most recent call last):
  File "internal/testpy/test_framework.py", line 238, in <module>
    main()
  File "internal/testpy/test_framework.py", line 57, in main
    input("Press Enter To Exit...")
EOFError

Exception caught at 2021-11-06 17:59:37.965145:
Traceback (most recent call last):
  File "internal/testpy/test_framework.py", line 238, in <module>
    main()
  File "internal/testpy/test_framework.py", line 57, in main
    input("Press Enter To Exit...")
EOFError

Exception caught at 2021-11-06 17:59:37.966108:
Traceback (most recent call last):
  File "internal/testpy/test_framework.py", line 238, in <module>
    main()
  File "internal/testpy/test_framework.py", line 57, in main
    input("Press Enter To Exit...")
EOFError

Exception caught at 2021-11-06 17:59:37.966989:
Traceback (most recent call last):
  File "internal/testpy/test_framework.py", line 238, in <module>
    main()
  File "internal/testpy/test_framework.py", line 57, in main
    input("Press Enter To Exit...")
EOFError

Exception caught at 2021-11-06 17:59:37.967708:
Traceback (most recent call last):
  File "internal/testpy/test_framework.py", line 238, in <module>
    main()
  File "internal/testpy/test_framework.py", line 57, in main
    input("Press Enter To Exit...")
EOFError

Exception caught at 2021-11-06 17:59:40.881860:
Traceback (most recent call last):
  File "internal/testpy/test_framework.py", line 238, in <module>
    main()
  File "internal/testpy/test_framework.py", line 57, in main
    input("Press Enter To Exit...")
EOFError: EOF when reading a line
